The second instance failed because 